<?xml version="1.0" ?>
<!-- =================================================================================== -->
<!-- |    This document was autogenerated by xacro from /home/ylo2/catkin_ws/src/legged_control/legged_unitree/legged_unitree_description/urdf/robot.xacro | -->
<!-- |    EDITING THIS FILE BY HAND IS NOT RECOMMENDED                                 | -->
<!-- =================================================================================== -->
<robot name="robot">
  <material name="black">
    <color rgba="0.0 0.0 0.0 1.0"/>
  </material>
  <material name="blue">
    <color rgba="0.0 0.0 0.8 1.0"/>
  </material>
  <material name="green">
    <color rgba="0.0 0.8 0.0 1.0"/>
  </material>
  <material name="grey">
    <color rgba="0.2 0.2 0.2 1.0"/>
  </material>
  <material name="silver">
    <color rgba="0.9137254901960784 0.9137254901960784 0.8470588235294118 1.0"/>
  </material>
  <material name="orange">
    <color rgba="1.0 0.4235294117647059 0.0392156862745098 1.0"/>
  </material>
  <material name="brown">
    <color rgba="0.8705882352941177 0.8117647058823529 0.7647058823529411 1.0"/>
  </material>
  <material name="red">
    <color rgba="0.8 0.0 0.0 1.0"/>
  </material>
  <material name="white">
    <color rgba="1.0 1.0 1.0 1.0"/>
  </material>
  <!-- ros_control plugin -->
  <gazebo>
    <plugin filename="liblegged_hw_sim.so" name="gazebo_ros_control">
      <robotNamespace>/</robotNamespace>
      <robotParam>legged_robot_description</robotParam>
      <robotSimType>legged_gazebo/LeggedHWSim</robotSimType>
    </plugin>
  </gazebo>
  <gazebo>
    <plugin filename="libgazebo_ros_p3d.so" name="p3d_base_controller">
      <alwaysOn>true</alwaysOn>
      <updateRate>1000.0</updateRate>
      <bodyName>base</bodyName>
      <topicName>ground_truth/state</topicName>
      <gaussianNoise>0</gaussianNoise>
      <frameName>world</frameName>
      <xyzOffsets>0 0 0</xyzOffsets>
      <rpyOffsets>0 0 0</rpyOffsets>
    </plugin>
  </gazebo>
  <gazebo reference="base_link">
    <maxVel>100.</maxVel>
    <kp>10000.</kp>
    <kd>0.</kd>
  </gazebo>
  <gazebo reference="stick_link">
    <mu1>0.2</mu1>
    <mu2>0.2</mu2>
    <material>Gazebo/White</material>
  </gazebo>
  <!-- LF leg -->
  <gazebo reference="LF_hip">
    <mu1>0.2</mu1>
    <mu2>0.2</mu2>
    <material>Gazebo/DarkGrey</material>
  </gazebo>
  <gazebo reference="LF_thigh">
    <mu1>0.2</mu1>
    <mu2>0.2</mu2>
    <self_collide>0</self_collide>
    <material>Gazebo/DarkGrey</material>
    <kp value="1000000.0"/>
    <kd value="1.0"/>
  </gazebo>
  <gazebo reference="LF_calf">
    <mu1>0.2</mu1>
    <mu2>0.2</mu2>
    <self_collide>1</self_collide>
  </gazebo>
  <gazebo reference="LF_FOOT">
    <mu1>0.6</mu1>
    <mu2>0.6</mu2>
    <self_collide>1</self_collide>
    <material>Gazebo/DarkGrey</material>
    <kp value="1000000.0"/>
    <kd value="1.0"/>
  </gazebo>
  <!-- RF leg -->
  <gazebo reference="RF_hip">
    <mu1>0.2</mu1>
    <mu2>0.2</mu2>
    <material>Gazebo/DarkGrey</material>
  </gazebo>
  <gazebo reference="RF_thigh">
    <mu1>0.2</mu1>
    <mu2>0.2</mu2>
    <self_collide>0</self_collide>
    <material>Gazebo/DarkGrey</material>
    <kp value="1000000.0"/>
    <kd value="1.0"/>
  </gazebo>
  <gazebo reference="RF_calf">
    <mu1>0.2</mu1>
    <mu2>0.2</mu2>
    <self_collide>1</self_collide>
  </gazebo>
  <gazebo reference="RF_FOOT">
    <mu1>0.6</mu1>
    <mu2>0.6</mu2>
    <self_collide>1</self_collide>
    <material>Gazebo/DarkGrey</material>
    <kp value="1000000.0"/>
    <kd value="1.0"/>
  </gazebo>
  <!-- LH leg -->
  <gazebo reference="LH_hip">
    <mu1>0.2</mu1>
    <mu2>0.2</mu2>
    <material>Gazebo/DarkGrey</material>
  </gazebo>
  <gazebo reference="LH_thigh">
    <mu1>0.2</mu1>
    <mu2>0.2</mu2>
    <self_collide>0</self_collide>
    <material>Gazebo/DarkGrey</material>
    <kp value="1000000.0"/>
    <kd value="1.0"/>
  </gazebo>
  <gazebo reference="LH_calf">
    <mu1>0.2</mu1>
    <mu2>0.2</mu2>
    <self_collide>1</self_collide>
  </gazebo>
  <gazebo reference="LH_FOOT">
    <mu1>0.6</mu1>
    <mu2>0.6</mu2>
    <self_collide>1</self_collide>
    <material>Gazebo/DarkGrey</material>
    <kp value="1000000.0"/>
    <kd value="1.0"/>
  </gazebo>
  <!-- RH leg -->
  <gazebo reference="RH_hip">
    <mu1>0.2</mu1>
    <mu2>0.2</mu2>
    <material>Gazebo/DarkGrey</material>
  </gazebo>
  <gazebo reference="RH_thigh">
    <mu1>0.2</mu1>
    <mu2>0.2</mu2>
    <self_collide>0</self_collide>
    <material>Gazebo/DarkGrey</material>
    <kp value="1000000.0"/>
    <kd value="1.0"/>
  </gazebo>
  <gazebo reference="RH_calf">
    <mu1>0.2</mu1>
    <mu2>0.2</mu2>
    <self_collide>1</self_collide>
  </gazebo>
  <gazebo reference="RH_FOOT">
    <mu1>0.6</mu1>
    <mu2>0.6</mu2>
    <self_collide>1</self_collide>
    <material>Gazebo/DarkGrey</material>
    <kp value="1000000.0"/>
    <kd value="1.0"/>
  </gazebo>
  <link name="base">
    <visual>
      <origin rpy="0 0 0" xyz="0.0 0.0 0.0"/>
      <geometry>
        <mesh filename="package://legged_unitree_description/meshes/a1/body/textured/ylo2_textured_body.dae" scale="1 1 1"/>
      </geometry>
    </visual>
    <collision>
      <origin rpy="0 0 0" xyz="0.0 0.0 0.0"/>
      <geometry>
        <box size="0.57 0.35 0.149"/>
      </geometry>
    </collision>
    <inertial>
      <origin rpy="0 0 0" xyz="0.02 0.00194 0.0"/>
      <mass value="6.0"/>
      <inertia ixx="0.0158533" ixy="-0.0001332" ixz="-0.0002403" iyy="0.04168" iyz="1.5299e-05" izz="0.04742"/>
    </inertial>
  </link>
  <joint name="abad_motors_joint" type="fixed">
    <parent link="base"/>
    <child link="abad_motors"/>
    <origin rpy="0 0 0" xyz="0 0 0"/>
  </joint>
  <link name="abad_motors">
    <visual>
      <origin rpy="0 0 0" xyz="0.0 0.0 0.0"/>
      <geometry>
        <mesh filename="package://legged_unitree_description/meshes/a1/body/textured/ylo2_textured_abad_motors.dae" scale="1 1 1"/>
      </geometry>
      <material name="white"/>
    </visual>
  </link>
  <joint name="covers_joint" type="fixed">
    <parent link="base"/>
    <child link="covers"/>
    <origin rpy="0 0 0" xyz="0 0 0"/>
  </joint>
  <link name="covers">
    <visual>
      <origin rpy="0 0 0" xyz="0.0 0.0 0.0"/>
      <geometry>
        <mesh filename="package://legged_unitree_description/meshes/a1/body/textured/ylo2_textured_cover.dae" scale="1 1 1"/>
      </geometry>
      <material name="orange"/>
    </visual>
  </link>
  <joint name="accessories_joint" type="fixed">
    <parent link="base"/>
    <child link="accessories"/>
    <origin rpy="0 0 0" xyz="0 0 0"/>
  </joint>
  <link name="accessories">
    <visual>
      <origin rpy="0 0 0" xyz="0.0 0.0 0.0"/>
      <geometry>
        <mesh filename="package://legged_unitree_description/meshes/a1/body/textured/accessories.dae" scale="1 1 1"/>
      </geometry>
      <material name="blue"/>
    </visual>
  </link>
  <joint name="d435_joint" type="fixed">
    <parent link="base"/>
    <child link="d435"/>
    <origin rpy="0 0 0" xyz="0 0 0"/>
  </joint>
  <link name="d435">
    <visual>
      <origin rpy="0 0 0" xyz="0.0 0.003 0.0"/>
      <geometry>
        <mesh filename="package://legged_unitree_description/meshes/a1/body/textured/ylo2_d435_textured.dae" scale="1 1 1"/>
      </geometry>
      <material name="black"/>
    </visual>
  </link>
  <joint name="t265_joint" type="fixed">
    <parent link="base"/>
    <child link="t265"/>
    <origin rpy="0 0 0" xyz="0 0 0"/>
  </joint>
  <link name="t265">
    <visual>
      <origin rpy="0 0 0" xyz="0.0 0.0 0.0"/>
      <geometry>
        <mesh filename="package://legged_unitree_description/meshes/a1/body/textured/ylo2_t265_textured.dae" scale="1 1.06 1.04"/>
      </geometry>
      <material name="black"/>
    </visual>
  </link>
  <!-- Imu is fixed to the base link -->
  <joint name="unitree_imu_joint" type="fixed">
    <origin rpy="0. 0. 0." xyz="0. 0. 0."/>
    <parent link="base"/>
    <child link="unitree_imu"/>
  </joint>
  <!-- Imu link -->
  <link name="unitree_imu">
    <inertial>
      <mass value="0.01"/>
      <origin rpy="0 0 0" xyz="0 0 0"/>
      <inertia ixx="0.000001" ixy="0" ixz="0" iyy="0.000001" iyz="0" izz="0.000001"/>
    </inertial>
    <visual>
      <origin rpy="0 0 0" xyz="0 0 0"/>
      <geometry>
        <box size="0.015 0.015 0.004"/>
      </geometry>
    </visual>
    <material name="orange">
      <color rgba="255 108 10 255"/>
    </material>
  </link>
  <gazebo reference="unitree_imu">
    <material>Gazebo/Orange</material>
  </gazebo>
  <gazebo reference="unitree_imu_joint">
    <disableFixedJointLumping>true</disableFixedJointLumping>
  </gazebo>
  <joint name="RF_HAA" type="revolute">
    <origin rpy="0 0 0" xyz="0.1695 -0.052000000000000005 0.024"/>
    <parent link="base"/>
    <child link="RF_hip"/>
    <axis xyz="1 0 0"/>
    <dynamics damping="0" friction="0"/>
    <limit effort="33.5" lower="-0.8028514559173915" upper="0.8028514559173915" velocity="21"/>
  </joint>
  <link name="RF_hip">
    <visual>
      <origin rpy="3.141592653589793 0 0" xyz="-0.055 0 0"/>
      <geometry>
        <mesh filename="package://legged_unitree_description/meshes/a1/leg/textured/ylo2texturedhip.dae" scale="1 1 1"/>
      </geometry>
      <material name="orange"/>
    </visual>
    <collision>
      <origin rpy="1.5707963267948966 0 0" xyz="0 0 0"/>
      <geometry>
        <cylinder length="0.06" radius="0.05"/>
      </geometry>
    </collision>
    <inertial>
      <origin rpy="0 0 0" xyz="-0.011957 -0.000306 0.000366"/>
      <mass value="0.599"/>
      <inertia ixx="0.0004159" ixy="-4.253e-06" ixz="3.68e-07" iyy="0.0007108" iyz="-2.15e-07" izz="0.0004707"/>
    </inertial>
  </link>
  <joint name="RF_HFE" type="revolute">
    <origin rpy="0 1.5707963267948966 0" xyz="0.0 -0.02 0"/>
    <parent link="RF_hip"/>
    <child link="RF_thigh"/>
    <axis xyz="0 1 0"/>
    <dynamics damping="0" friction="0"/>
    <limit effort="33.5" lower="-1.0471975511965976" upper="4.1887902047863905" velocity="21"/>
  </joint>
  <link name="RF_thigh">
    <visual>
      <origin rpy="0 0 0" xyz="0 0 0"/>
      <geometry>
        <mesh filename="package://legged_unitree_description/meshes/a1/leg/textured/ylo2_textured_upper_leg.dae" scale="1 -1 1"/>
      </geometry>
      <material name="orange"/>
    </visual>
    <collision>
      <origin rpy="0 1.5707963267948966 0" xyz="0 0 -0.1005"/>
      <geometry>
        <box size="0.201 0.0374 0.043"/>
      </geometry>
    </collision>
    <inertial>
      <origin rpy="0 0 0" xyz="-0.000684 0.010999 -0.035487"/>
      <mass value="1.08"/>
      <inertia ixx="0.005666803" ixy="-3.597e-06" ixz="0.000491446" iyy="0.005847229" iyz="-1.0086e-05" izz="0.000369811"/>
    </inertial>
  </link>
  <joint name="RF_KFE" type="revolute">
    <origin rpy="0 -3.141592653589793 0" xyz="-0.001 -0.075 -0.201"/>
    <parent link="RF_thigh"/>
    <child link="RF_calf"/>
    <axis xyz="0 1 0"/>
    <dynamics damping="0" friction="0"/>
    <limit effort="33.5" lower="-2.6965336943312392" upper="-0.9162978572970231" velocity="21"/>
  </joint>
  <link name="RF_calf">
    <visual>
      <origin rpy="0 0 0" xyz="0 0 0"/>
      <geometry>
        <mesh filename="package://legged_unitree_description/meshes/a1/leg/textured/lower_leg.dae" scale="1 1 1"/>
      </geometry>
      <material name="orange"/>
    </visual>
    <collision>
      <origin rpy="0 1.5707963267948966 0" xyz="0 0 -0.115"/>
      <geometry>
        <mesh filename="package://legged_unitree_description/meshes/a1/leg/fl_lower_leg_collision.stl" scale="1 1 1"/>
      </geometry>
    </collision>
    <inertial>
      <origin rpy="0 0 0" xyz="0.000252 0.000194 -0.05192"/>
      <mass value="0.265"/>
      <inertia ixx="0.0004583" ixy="-9.5e-08" ixz="2.6512e-05" iyy="0.0004675" iyz="2.77e-07" izz="2.9145e-05"/>
    </inertial>
  </link>
  <joint name="RF_foot_fixed" type="fixed">
    <origin rpy="0 0 0" xyz="0 0 -0.23"/>
    <parent link="RF_calf"/>
    <child link="RF_FOOT"/>
  </joint>
  <link name="RF_FOOT">
    <visual>
      <origin rpy="0 0 0" xyz="0.009 0.0 0.069"/>
      <geometry>
        <mesh filename="package://legged_unitree_description/meshes/a1/leg/fl_foot.dae" scale="1 1 1"/>
      </geometry>
      <material name="orange"/>
    </visual>
    <collision>
      <origin rpy="0 0 0" xyz="0.009 0.0 0.069"/>
      <geometry>
        <mesh filename="package://legged_unitree_description/meshes/a1/legfh/fl_foot.dae" scale="1.0 1.0 1.0"/>
        --&gt;
                
      </geometry>
    </collision>
    <inertial>
      <mass value="0.078"/>
      <inertia ixx="2.19102e-05" ixy="0.0" ixz="0.0" iyy="2.19102e-05" iyz="0.0" izz="2.19102e-05"/>
    </inertial>
  </link>
  <gazebo reference="RF_foot_fixed">
    <disableFixedJointLumping>true</disableFixedJointLumping>
  </gazebo>
  <transmission name="RF_HAA_tran">
    <type>transmission_interface/SimpleTransmission</type>
    <joint name="RF_HAA">
      <hardwareInterface>hardware_interface/EffortJointInterface</hardwareInterface>
    </joint>
    <actuator name="RF_HAA_motor">
      <hardwareInterface>hardware_interface/EffortJointInterface</hardwareInterface>
      <mechanicalReduction>1</mechanicalReduction>
    </actuator>
  </transmission>
  <transmission name="RF_HFE_tran">
    <type>transmission_interface/SimpleTransmission</type>
    <joint name="RF_HFE">
      <hardwareInterface>hardware_interface/EffortJointInterface</hardwareInterface>
    </joint>
    <actuator name="RF_HFE_motor">
      <hardwareInterface>hardware_interface/EffortJointInterface</hardwareInterface>
      <mechanicalReduction>1</mechanicalReduction>
    </actuator>
  </transmission>
  <transmission name="RF_KFE_tran">
    <type>transmission_interface/SimpleTransmission</type>
    <joint name="RF_KFE">
      <hardwareInterface>hardware_interface/EffortJointInterface</hardwareInterface>
    </joint>
    <actuator name="RF_KFE_motor">
      <hardwareInterface>hardware_interface/EffortJointInterface</hardwareInterface>
      <mechanicalReduction>1</mechanicalReduction>
    </actuator>
  </transmission>
  <joint name="LF_HAA" type="revolute">
    <origin rpy="0 0 0" xyz="0.1695 0.063 0.024"/>
    <parent link="base"/>
    <child link="LF_hip"/>
    <axis xyz="1 0 0"/>
    <dynamics damping="0" friction="0"/>
    <limit effort="33.5" lower="-0.8028514559173915" upper="0.8028514559173915" velocity="21"/>
  </joint>
  <link name="LF_hip">
    <visual>
      <origin rpy="0 0 0" xyz="-0.055 0 0"/>
      <geometry>
        <mesh filename="package://legged_unitree_description/meshes/a1/leg/textured/ylo2texturedhip.dae" scale="1 1 1"/>
      </geometry>
      <material name="orange"/>
    </visual>
    <collision>
      <origin rpy="1.5707963267948966 0 0" xyz="0 0 0"/>
      <geometry>
        <cylinder length="0.06" radius="0.05"/>
      </geometry>
    </collision>
    <inertial>
      <origin rpy="0 0 0" xyz="-0.011957 0.000306 0.000366"/>
      <mass value="0.599"/>
      <inertia ixx="0.0004159" ixy="4.253e-06" ixz="3.68e-07" iyy="0.0007108" iyz="2.15e-07" izz="0.0004707"/>
    </inertial>
  </link>
  <joint name="LF_HFE" type="revolute">
    <origin rpy="0 1.5707963267948966 0" xyz="0.0 0.02 0"/>
    <parent link="LF_hip"/>
    <child link="LF_thigh"/>
    <axis xyz="0 1 0"/>
    <dynamics damping="0" friction="0"/>
    <limit effort="33.5" lower="-1.0471975511965976" upper="4.1887902047863905" velocity="21"/>
  </joint>
  <link name="LF_thigh">
    <visual>
      <origin rpy="0 0 0" xyz="0 0 0"/>
      <geometry>
        <mesh filename="package://legged_unitree_description/meshes/a1/leg/textured/ylo2_textured_upper_leg.dae" scale="1 1 1"/>
      </geometry>
      <material name="orange"/>
    </visual>
    <collision>
      <origin rpy="0 1.5707963267948966 0" xyz="0 0 -0.1005"/>
      <geometry>
        <box size="0.201 0.0374 0.043"/>
      </geometry>
    </collision>
    <inertial>
      <origin rpy="0 0 0" xyz="-0.000684 -0.010999 -0.035487"/>
      <mass value="1.08"/>
      <inertia ixx="0.005666803" ixy="3.597e-06" ixz="0.000491446" iyy="0.005847229" iyz="1.0086e-05" izz="0.000369811"/>
    </inertial>
  </link>
  <joint name="LF_KFE" type="revolute">
    <origin rpy="0 -3.141592653589793 0" xyz="-0.001 0.075 -0.201"/>
    <parent link="LF_thigh"/>
    <child link="LF_calf"/>
    <axis xyz="0 1 0"/>
    <dynamics damping="0" friction="0"/>
    <limit effort="33.5" lower="-2.6965336943312392" upper="-0.9162978572970231" velocity="21"/>
  </joint>
  <link name="LF_calf">
    <visual>
      <origin rpy="0 0 0" xyz="0 0 0"/>
      <geometry>
        <mesh filename="package://legged_unitree_description/meshes/a1/leg/textured/lower_leg.dae" scale="1 1 1"/>
      </geometry>
      <material name="orange"/>
    </visual>
    <collision>
      <origin rpy="0 1.5707963267948966 0" xyz="0 0 -0.115"/>
      <geometry>
        <mesh filename="package://legged_unitree_description/meshes/a1/leg/fl_lower_leg_collision.stl" scale="1 1 1"/>
      </geometry>
    </collision>
    <inertial>
      <origin rpy="0 0 0" xyz="0.000252 0.000194 -0.05192"/>
      <mass value="0.265"/>
      <inertia ixx="0.0004583" ixy="-9.5e-08" ixz="2.6512e-05" iyy="0.0004675" iyz="2.77e-07" izz="2.9145e-05"/>
    </inertial>
  </link>
  <joint name="LF_foot_fixed" type="fixed">
    <origin rpy="0 0 0" xyz="0 0 -0.23"/>
    <parent link="LF_calf"/>
    <child link="LF_FOOT"/>
  </joint>
  <link name="LF_FOOT">
    <visual>
      <origin rpy="0 0 0" xyz="0.009 0.002 0.069"/>
      <geometry>
        <mesh filename="package://legged_unitree_description/meshes/a1/leg/fl_foot.dae" scale="1 1 1"/>
      </geometry>
      <material name="orange"/>
    </visual>
    <collision>
      <origin rpy="0 0 0" xyz="0.009 0.002 0.069"/>
      <geometry>
        <mesh filename="package://legged_unitree_description/meshes/a1/legfh/fl_foot.dae" scale="1.0 1.0 1.0"/>
        --&gt;
                
      </geometry>
    </collision>
    <inertial>
      <mass value="0.078"/>
      <inertia ixx="2.19102e-05" ixy="0.0" ixz="0.0" iyy="2.19102e-05" iyz="0.0" izz="2.19102e-05"/>
    </inertial>
  </link>
  <gazebo reference="LF_foot_fixed">
    <disableFixedJointLumping>true</disableFixedJointLumping>
  </gazebo>
  <transmission name="LF_HAA_tran">
    <type>transmission_interface/SimpleTransmission</type>
    <joint name="LF_HAA">
      <hardwareInterface>hardware_interface/EffortJointInterface</hardwareInterface>
    </joint>
    <actuator name="LF_HAA_motor">
      <hardwareInterface>hardware_interface/EffortJointInterface</hardwareInterface>
      <mechanicalReduction>1</mechanicalReduction>
    </actuator>
  </transmission>
  <transmission name="LF_HFE_tran">
    <type>transmission_interface/SimpleTransmission</type>
    <joint name="LF_HFE">
      <hardwareInterface>hardware_interface/EffortJointInterface</hardwareInterface>
    </joint>
    <actuator name="LF_HFE_motor">
      <hardwareInterface>hardware_interface/EffortJointInterface</hardwareInterface>
      <mechanicalReduction>1</mechanicalReduction>
    </actuator>
  </transmission>
  <transmission name="LF_KFE_tran">
    <type>transmission_interface/SimpleTransmission</type>
    <joint name="LF_KFE">
      <hardwareInterface>hardware_interface/EffortJointInterface</hardwareInterface>
    </joint>
    <actuator name="LF_KFE_motor">
      <hardwareInterface>hardware_interface/EffortJointInterface</hardwareInterface>
      <mechanicalReduction>1</mechanicalReduction>
    </actuator>
  </transmission>
  <joint name="RH_HAA" type="revolute">
    <origin rpy="0 0 0" xyz="-0.20950000000000002 -0.052000000000000005 0.024"/>
    <parent link="base"/>
    <child link="RH_hip"/>
    <axis xyz="1 0 0"/>
    <dynamics damping="0" friction="0"/>
    <limit effort="33.5" lower="-0.8028514559173915" upper="0.8028514559173915" velocity="21"/>
  </joint>
  <link name="RH_hip">
    <visual>
      <origin rpy="3.141592653589793 3.141592653589793 0" xyz="0.055 0 0"/>
      <geometry>
        <mesh filename="package://legged_unitree_description/meshes/a1/leg/textured/ylo2texturedhip.dae" scale="1 1 1"/>
      </geometry>
      <material name="orange"/>
    </visual>
    <collision>
      <origin rpy="1.5707963267948966 0 0" xyz="0 0 0"/>
      <geometry>
        <cylinder length="0.06" radius="0.05"/>
      </geometry>
    </collision>
    <inertial>
      <origin rpy="0 0 0" xyz="0.011957 -0.000306 0.000366"/>
      <mass value="0.599"/>
      <inertia ixx="0.0004159" ixy="4.253e-06" ixz="-3.68e-07" iyy="0.0007108" iyz="-2.15e-07" izz="0.0004707"/>
    </inertial>
  </link>
  <joint name="RH_HFE" type="revolute">
    <origin rpy="0 1.5707963267948966 0" xyz="0.0 -0.02 0"/>
    <parent link="RH_hip"/>
    <child link="RH_thigh"/>
    <axis xyz="0 1 0"/>
    <dynamics damping="0" friction="0"/>
    <limit effort="33.5" lower="-1.0471975511965976" upper="4.1887902047863905" velocity="21"/>
  </joint>
  <link name="RH_thigh">
    <visual>
      <origin rpy="0 0 0" xyz="0 0 0"/>
      <geometry>
        <mesh filename="package://legged_unitree_description/meshes/a1/leg/textured/ylo2_textured_upper_leg.dae" scale="1 -1 1"/>
      </geometry>
      <material name="orange"/>
    </visual>
    <collision>
      <origin rpy="0 1.5707963267948966 0" xyz="0 0 -0.1005"/>
      <geometry>
        <box size="0.201 0.0374 0.043"/>
      </geometry>
    </collision>
    <inertial>
      <origin rpy="0 0 0" xyz="-0.000684 0.010999 -0.035487"/>
      <mass value="1.08"/>
      <inertia ixx="0.005666803" ixy="-3.597e-06" ixz="0.000491446" iyy="0.005847229" iyz="-1.0086e-05" izz="0.000369811"/>
    </inertial>
  </link>
  <joint name="RH_KFE" type="revolute">
    <origin rpy="0 -3.141592653589793 0" xyz="-0.001 -0.075 -0.201"/>
    <parent link="RH_thigh"/>
    <child link="RH_calf"/>
    <axis xyz="0 1 0"/>
    <dynamics damping="0" friction="0"/>
    <limit effort="33.5" lower="-2.6965336943312392" upper="-0.9162978572970231" velocity="21"/>
  </joint>
  <link name="RH_calf">
    <visual>
      <origin rpy="0 0 0" xyz="0 0 0"/>
      <geometry>
        <mesh filename="package://legged_unitree_description/meshes/a1/leg/textured/lower_leg.dae" scale="1 1 1"/>
      </geometry>
      <material name="orange"/>
    </visual>
    <collision>
      <origin rpy="0 1.5707963267948966 0" xyz="0 0 -0.115"/>
      <geometry>
        <mesh filename="package://legged_unitree_description/meshes/a1/leg/fl_lower_leg_collision.stl" scale="1 1 1"/>
      </geometry>
    </collision>
    <inertial>
      <origin rpy="0 0 0" xyz="0.000252 0.000194 -0.05192"/>
      <mass value="0.265"/>
      <inertia ixx="0.0004583" ixy="-9.5e-08" ixz="2.6512e-05" iyy="0.0004675" iyz="2.77e-07" izz="2.9145e-05"/>
    </inertial>
  </link>
  <joint name="RH_foot_fixed" type="fixed">
    <origin rpy="0 0 0" xyz="0 0 -0.23"/>
    <parent link="RH_calf"/>
    <child link="RH_FOOT"/>
  </joint>
  <link name="RH_FOOT">
    <visual>
      <origin rpy="0 0 0" xyz="0.009 0.0 0.069"/>
      <geometry>
        <mesh filename="package://legged_unitree_description/meshes/a1/leg/fl_foot.dae" scale="1 1 1"/>
      </geometry>
      <material name="orange"/>
    </visual>
    <collision>
      <origin rpy="0 0 0" xyz="0.009 0.0 0.069"/>
      <geometry>
        <mesh filename="package://legged_unitree_description/meshes/a1/legfh/fl_foot.dae" scale="1.0 1.0 1.0"/>
        --&gt;
                
      </geometry>
    </collision>
    <inertial>
      <mass value="0.078"/>
      <inertia ixx="2.19102e-05" ixy="0.0" ixz="0.0" iyy="2.19102e-05" iyz="0.0" izz="2.19102e-05"/>
    </inertial>
  </link>
  <gazebo reference="RH_foot_fixed">
    <disableFixedJointLumping>true</disableFixedJointLumping>
  </gazebo>
  <transmission name="RH_HAA_tran">
    <type>transmission_interface/SimpleTransmission</type>
    <joint name="RH_HAA">
      <hardwareInterface>hardware_interface/EffortJointInterface</hardwareInterface>
    </joint>
    <actuator name="RH_HAA_motor">
      <hardwareInterface>hardware_interface/EffortJointInterface</hardwareInterface>
      <mechanicalReduction>1</mechanicalReduction>
    </actuator>
  </transmission>
  <transmission name="RH_HFE_tran">
    <type>transmission_interface/SimpleTransmission</type>
    <joint name="RH_HFE">
      <hardwareInterface>hardware_interface/EffortJointInterface</hardwareInterface>
    </joint>
    <actuator name="RH_HFE_motor">
      <hardwareInterface>hardware_interface/EffortJointInterface</hardwareInterface>
      <mechanicalReduction>1</mechanicalReduction>
    </actuator>
  </transmission>
  <transmission name="RH_KFE_tran">
    <type>transmission_interface/SimpleTransmission</type>
    <joint name="RH_KFE">
      <hardwareInterface>hardware_interface/EffortJointInterface</hardwareInterface>
    </joint>
    <actuator name="RH_KFE_motor">
      <hardwareInterface>hardware_interface/EffortJointInterface</hardwareInterface>
      <mechanicalReduction>1</mechanicalReduction>
    </actuator>
  </transmission>
  <joint name="LH_HAA" type="revolute">
    <origin rpy="0 0 0" xyz="-0.20950000000000002 0.063 0.024"/>
    <parent link="base"/>
    <child link="LH_hip"/>
    <axis xyz="1 0 0"/>
    <dynamics damping="0" friction="0"/>
    <limit effort="33.5" lower="-0.8028514559173915" upper="0.8028514559173915" velocity="21"/>
  </joint>
  <link name="LH_hip">
    <visual>
      <origin rpy="0 3.141592653589793 0" xyz="0.055 0 0"/>
      <geometry>
        <mesh filename="package://legged_unitree_description/meshes/a1/leg/textured/ylo2texturedhip.dae" scale="1 1 1"/>
      </geometry>
      <material name="orange"/>
    </visual>
    <collision>
      <origin rpy="1.5707963267948966 0 0" xyz="0 0 0"/>
      <geometry>
        <cylinder length="0.06" radius="0.05"/>
      </geometry>
    </collision>
    <inertial>
      <origin rpy="0 0 0" xyz="0.011957 0.000306 0.000366"/>
      <mass value="0.599"/>
      <inertia ixx="0.0004159" ixy="-4.253e-06" ixz="-3.68e-07" iyy="0.0007108" iyz="2.15e-07" izz="0.0004707"/>
    </inertial>
  </link>
  <joint name="LH_HFE" type="revolute">
    <origin rpy="0 1.5707963267948966 0" xyz="0.0 0.02 0"/>
    <parent link="LH_hip"/>
    <child link="LH_thigh"/>
    <axis xyz="0 1 0"/>
    <dynamics damping="0" friction="0"/>
    <limit effort="33.5" lower="-1.0471975511965976" upper="4.1887902047863905" velocity="21"/>
  </joint>
  <link name="LH_thigh">
    <visual>
      <origin rpy="0 0 0" xyz="0 0 0"/>
      <geometry>
        <mesh filename="package://legged_unitree_description/meshes/a1/leg/textured/ylo2_textured_upper_leg.dae" scale="1 1 1"/>
      </geometry>
      <material name="orange"/>
    </visual>
    <collision>
      <origin rpy="0 1.5707963267948966 0" xyz="0 0 -0.1005"/>
      <geometry>
        <box size="0.201 0.0374 0.043"/>
      </geometry>
    </collision>
    <inertial>
      <origin rpy="0 0 0" xyz="-0.000684 -0.010999 -0.035487"/>
      <mass value="1.08"/>
      <inertia ixx="0.005666803" ixy="3.597e-06" ixz="0.000491446" iyy="0.005847229" iyz="1.0086e-05" izz="0.000369811"/>
    </inertial>
  </link>
  <joint name="LH_KFE" type="revolute">
    <origin rpy="0 -3.141592653589793 0" xyz="-0.001 0.075 -0.201"/>
    <parent link="LH_thigh"/>
    <child link="LH_calf"/>
    <axis xyz="0 1 0"/>
    <dynamics damping="0" friction="0"/>
    <limit effort="33.5" lower="-2.6965336943312392" upper="-0.9162978572970231" velocity="21"/>
  </joint>
  <link name="LH_calf">
    <visual>
      <origin rpy="0 0 0" xyz="0 0 0"/>
      <geometry>
        <mesh filename="package://legged_unitree_description/meshes/a1/leg/textured/lower_leg.dae" scale="1 1 1"/>
      </geometry>
      <material name="orange"/>
    </visual>
    <collision>
      <origin rpy="0 1.5707963267948966 0" xyz="0 0 -0.115"/>
      <geometry>
        <mesh filename="package://legged_unitree_description/meshes/a1/leg/fl_lower_leg_collision.stl" scale="1 1 1"/>
      </geometry>
    </collision>
    <inertial>
      <origin rpy="0 0 0" xyz="0.000252 0.000194 -0.05192"/>
      <mass value="0.265"/>
      <inertia ixx="0.0004583" ixy="-9.5e-08" ixz="2.6512e-05" iyy="0.0004675" iyz="2.77e-07" izz="2.9145e-05"/>
    </inertial>
  </link>
  <joint name="LH_foot_fixed" type="fixed">
    <origin rpy="0 0 0" xyz="0 0 -0.23"/>
    <parent link="LH_calf"/>
    <child link="LH_FOOT"/>
  </joint>
  <link name="LH_FOOT">
    <visual>
      <origin rpy="0 0 0" xyz="0.009 0.002 0.069"/>
      <geometry>
        <mesh filename="package://legged_unitree_description/meshes/a1/leg/fl_foot.dae" scale="1 1 1"/>
      </geometry>
      <material name="orange"/>
    </visual>
    <collision>
      <origin rpy="0 0 0" xyz="0.009 0.002 0.069"/>
      <geometry>
        <mesh filename="package://legged_unitree_description/meshes/a1/legfh/fl_foot.dae" scale="1.0 1.0 1.0"/>
        --&gt;
                
      </geometry>
    </collision>
    <inertial>
      <mass value="0.078"/>
      <inertia ixx="2.19102e-05" ixy="0.0" ixz="0.0" iyy="2.19102e-05" iyz="0.0" izz="2.19102e-05"/>
    </inertial>
  </link>
  <gazebo reference="LH_foot_fixed">
    <disableFixedJointLumping>true</disableFixedJointLumping>
  </gazebo>
  <transmission name="LH_HAA_tran">
    <type>transmission_interface/SimpleTransmission</type>
    <joint name="LH_HAA">
      <hardwareInterface>hardware_interface/EffortJointInterface</hardwareInterface>
    </joint>
    <actuator name="LH_HAA_motor">
      <hardwareInterface>hardware_interface/EffortJointInterface</hardwareInterface>
      <mechanicalReduction>1</mechanicalReduction>
    </actuator>
  </transmission>
  <transmission name="LH_HFE_tran">
    <type>transmission_interface/SimpleTransmission</type>
    <joint name="LH_HFE">
      <hardwareInterface>hardware_interface/EffortJointInterface</hardwareInterface>
    </joint>
    <actuator name="LH_HFE_motor">
      <hardwareInterface>hardware_interface/EffortJointInterface</hardwareInterface>
      <mechanicalReduction>1</mechanicalReduction>
    </actuator>
  </transmission>
  <transmission name="LH_KFE_tran">
    <type>transmission_interface/SimpleTransmission</type>
    <joint name="LH_KFE">
      <hardwareInterface>hardware_interface/EffortJointInterface</hardwareInterface>
    </joint>
    <actuator name="LH_KFE_motor">
      <hardwareInterface>hardware_interface/EffortJointInterface</hardwareInterface>
      <mechanicalReduction>1</mechanicalReduction>
    </actuator>
  </transmission>
</robot>

